Workbook

Sheet Notes
A1: READ ME
A4: The table contains a hidden column. This is used for calcuations in the Figures Sheet. | K4: Figures Formulas
A5: To unhide this column, right click the gap below and click 'unhide'
K6: Note: All formulas have the '=' removed so they're not active
K8: DATE(2026, 1, 1) + SEQUENCE(365, 1, 0, 1) | W8: Filtered to week days only
K9: This is how the dates have been produced. It begins by starting with 01-01-2026
K10: (Excel does it backwards so the formula goes YEAR, MONTH#, DAY#)
W11: This assigns the cell 'c3' a number relating to the day of the week.
K12: It then creates 365 rows, in 1 column, starting at 0 | W12: Monday is 1, Tuesday 2 etc
K13: (in this case, our first date) and going down by 1 date a time | W13: If this does not apply to all cells, double click the bottom right of the cell and it'll apply to all rows
K14: SEQUENCE(rows, columns, start position, step)
K15: Step simply means how much we should change when going to the next row | W15: I then utilised a spare sheet ''Filter Page' to hide the backend and filtered our sequence
K16: E.g., 1,2,3,4,5 would be a step of 1. Whereas 1,3,5,7,9 would be a step of 2 | W16: based on our workweek (date needs to be equal to or less than 5)
K18: SUMIF(Table1[Date Typed], Figures!B2, Table1[Hidden column for calcs]) | W18: Resulting in us only seeing workdays on the filter page.
K19: This is what totals our time for the day. It sums all the times from our 'Letter Tracking' table for each of the days. | W19: If you want the weekdays as well, don't filter and use the below formula for dates instead
W20: DATE(2026, 1, 1) + SEQUENCE(365, 1, 0, 1)
K21: This is because it looks at table1 (letter tracking table) to see if there is a date in the date column
K22: If there is a date, it checks the table in 'figures' to see if there is the corresponding date and sums all the times | W22: Filter sheet was hidden. To find it again, right click any of the sheets and 'unhide'
K23: for that date from our hidden column and puts the sum into our figures table
K24: Note: if you are typing multiple letters from 1 dictation. Put the 2nd letter as 0:00 else it will skew
K25: your times typed. E.g, if you had a letter and a ref in 1 dictation of 8:00 and recorded it as 2 letters
K26: both of 8 minutes long then your time typed will artificially be 16 minutes and not 8
K28: COUNTIF(Table1[Date Typed], Figures!B2)
K29: This tells us how many letters. It simply counts how many letters were typed on a specific date.
K30: As such, it checks the 'Date Typed' column in our 'Letter Tracking' table and counts each time
K31: there is an entry and puts that count next to the related date in our 'Figures' table | Z31: This box will appear, click the sheet you want to unhide
K33: Note: If you currently don't count additional letters to you’re the figures you send then you may
K34: have to manually/mentally remove when sending if you've done additional such as 5-year Letrozole letter
A37: Changing Spreadsheet formula guide | N37: Letter Tracking Table General Use
A39: I only made the tracking table go to 2000 rows (1999 letters). | N39: Type times as: mm:ss - hidden column does the calculations for it
A40: At some point you will need to use another table, therefore I
A41: added a spare table which has the same formulas as that of | N41: The base table has no fill. However, it is setup to colour rows based on a few conditions.
A42: the original. | N42: First and easiest. If you put 'y' in the authorised column then it will turn green
A44: However, this will then break the figures tracking as it is tracking the
A45: original table specifically.
A46: To fix this, we need to first copy the current tracked figures. E.g., copy and paste
A47: from figures into a separate area. Potentially to the side of the table.
A48: Might not be needed if changing formula from date down of when we change sheets
A49: Then we change the formula from the date we change sheets. E.,g, if we change | N49: Secondly. If a letter was typed 14 or more days ago AND 'authorised' column has 'n' then it will auto highlight red.
A50: from the 1st of April. We'd do the following:
...

Sheet Figures
B2: Date Typed (Workdays) | C2: Total Length Typed | D2: #Letters typed
B3: {=_xlfn._xlws.FILTER('Filter Page'!C3:C367, 'Filter Page'!D3:D367<=5)} -> 46023 | C3: =SUMIF(Table1[Date Typed], Figures!B3, Table1[Hidden column for calcs]) -> 0 | D3: =COUNTIF(Table1[Date Typed], Figures!B3) -> 1
B4: 46024 | C4: =SUMIF(Table1[Date Typed], Figures!B4, Table1[Hidden column for calcs]) -> 0 | D4: =COUNTIF(Table1[Date Typed], Figures!B4) -> 0
B5: 46027 | C5: =SUMIF(Table1[Date Typed], Figures!B5, Table1[Hidden column for calcs]) -> 0 | D5: =COUNTIF(Table1[Date Typed], Figures!B5) -> 0
B6: 46028 | C6: =SUMIF(Table1[Date Typed], Figures!B6, Table1[Hidden column for calcs]) -> 0 | D6: =COUNTIF(Table1[Date Typed], Figures!B6) -> 0
B7: 46029 | C7: =SUMIF(Table1[Date Typed], Figures!B7, Table1[Hidden column for calcs]) -> 0 | D7: =COUNTIF(Table1[Date Typed], Figures!B7) -> 0
B8: 46030 | C8: =SUMIF(Table1[Date Typed], Figures!B8, Table1[Hidden column for calcs]) -> 0 | D8: =COUNTIF(Table1[Date Typed], Figures!B8) -> 0
B9: 46031 | C9: =SUMIF(Table1[Date Typed], Figures!B9, Table1[Hidden column for calcs]) -> 0 | D9: =COUNTIF(Table1[Date Typed], Figures!B9) -> 0
B10: 46034 | C10: =SUMIF(Table1[Date Typed], Figures!B10, Table1[Hidden column for calcs]) -> 0 | D10: =COUNTIF(Table1[Date Typed], Figures!B10) -> 0
B11: 46035 | C11: =SUMIF(Table1[Date Typed], Figures!B11, Table1[Hidden column for calcs]) -> 0 | D11: =COUNTIF(Table1[Date Typed], Figures!B11) -> 0
B12: 46036 | C12: =SUMIF(Table1[Date Typed], Figures!B12, Table1[Hidden column for calcs]) -> 0 | D12: =COUNTIF(Table1[Date Typed], Figures!B12) -> 0
B13: 46037 | C13: =SUMIF(Table1[Date Typed], Figures!B13, Table1[Hidden column for calcs]) -> 0 | D13: =COUNTIF(Table1[Date Typed], Figures!B13) -> 0
B14: 46038 | C14: =SUMIF(Table1[Date Typed], Figures!B14, Table1[Hidden column for calcs]) -> 0 | D14: =COUNTIF(Table1[Date Typed], Figures!B14) -> 0
B15: 46041 | C15: =SUMIF(Table1[Date Typed], Figures!B15, Table1[Hidden column for calcs]) -> 0 | D15: =COUNTIF(Table1[Date Typed], Figures!B15) -> 0
... B263: 46387 | C263: =SUMIF(Table1[Date Typed], Figures!B263, Table1[Hidden column for calcs]) -> 0 | D263: =COUNTIF(Table1[Date Typed], Figures!B263) -> 0
C264: =SUMIF(Table1[Date Typed], Figures!B264, Table1[Hidden column for calcs]) -> 0 | D264: =COUNTIF(Table1[Date Typed], Figures!B264) -> 0
C265: =SUMIF(Table1[Date Typed], Figures!B265, Table1[Hidden column for calcs]) -> 0 | D265: =COUNTIF(Table1[Date Typed], Figures!B265) -> 0
C266: =SUMIF(Table1[Date Typed], Figures!B266, Table1[Hidden column for calcs]) -> 0 | D266: =COUNTIF(Table1[Date Typed], Figures!B266) -> 0
C267: =SUMIF(Table1[Date Typed], Figures!B267, Table1[Hidden column for calcs]) -> 0 | D267: =COUNTIF(Table1[Date Typed], Figures!B267) -> 0
C268: =SUMIF(Table1[Date Typed], Figures!B268, Table1[Hidden column for calcs]) -> 0 | D268: =COUNTIF(Table1[Date Typed], Figures!B268) -> 0
C269: =SUMIF(Table1[Date Typed], Figures!B269, Table1[Hidden column for calcs]) -> 0 | D269: =COUNTIF(Table1[Date Typed], Figures!B269) -> 0
C270: =SUMIF(Table1[Date Typed], Figures!B270, Table1[Hidden column for calcs]) -> 0 | D270: =COUNTIF(Table1[Date Typed], Figures!B270) -> 0
C271: =SUMIF(Table1[Date Typed], Figures!B271, Table1[Hidden column for calcs]) -> 0 | D271: =COUNTIF(Table1[Date Typed], Figures!B271) -> 0
C272: =SUMIF(Table1[Date Typed], Figures!B272, Table1[Hidden column for calcs]) -> 0 | D272: =COUNTIF(Table1[Date Typed], Figures!B272) -> 0
C273: =SUMIF(Table1[Date Typed], Figures!B273, Table1[Hidden column for calcs]) -> 0 | D273: =COUNTIF(Table1[Date Typed], Figures!B273) -> 0
C274: =SUMIF(Table1[Date Typed], Figures!B274, Table1[Hidden column for calcs]) -> 0 | D274: =COUNTIF(Table1[Date Typed], Figures!B274) -> 0
C275: =SUMIF(Table1[Date Typed], Figures!B275, Table1[Hidden column for calcs]) -> 0 | D275: =COUNTIF(Table1[Date Typed], Figures!B275) -> 0
... C367: =SUMIF(Table1[Date Typed], Figures!B367, Table1[Hidden column for calcs]) -> 0 | D367: =COUNTIF(Table1[Date Typed], Figures!B367) -> 0

Sheet Filter Page
C3: {=DATE(2026, 1, 1) + _xlfn.SEQUENCE(365, 1, 0, 1)} -> 46023 | D3: =WEEKDAY(C3, 2) -> 4 | E3: {=_xlfn._xlws.FILTER(C3:C367, D3:D367<=5)} -> 46023 | F3: {=TEXT(_xlfn.ANCHORARRAY(E3), "dddd")} -> Thursday
C4: 46024 | D4: =WEEKDAY(C4, 2) -> 5 | E4: 46024 | F4: Friday
C5: 46025 | D5: =WEEKDAY(C5, 2) -> 6 | E5: 46027 | F5: Monday
C6: 46026 | D6: =WEEKDAY(C6, 2) -> 7 | E6: 46028 | F6: Tuesday
C7: 46027 | D7: =WEEKDAY(C7, 2) -> 1 | E7: 46029 | F7: Wednesday
C8: 46028 | D8: =WEEKDAY(C8, 2) -> 2 | E8: 46030 | F8: Thursday
C9: 46029 | D9: =WEEKDAY(C9, 2) -> 3 | E9: 46031 | F9: Friday
C10: 46030 | D10: =WEEKDAY(C10, 2) -> 4 | E10: 46034 | F10: Monday
C11: 46031 | D11: =WEEKDAY(C11, 2) -> 5 | E11: 46035 | F11: Tuesday
C12: 46032 | D12: =WEEKDAY(C12, 2) -> 6 | E12: 46036 | F12: Wednesday
C13: 46033 | D13: =WEEKDAY(C13, 2) -> 7 | E13: 46037 | F13: Thursday
C14: 46034 | D14: =WEEKDAY(C14, 2) -> 1 | E14: 46038 | F14: Friday
C15: 46035 | D15: =WEEKDAY(C15, 2) -> 2 | E15: 46041 | F15: Monday
... C263: 46283 | D263: =WEEKDAY(C263, 2) -> 5 | E263: 46387 | F263: Thursday
C264: 46284 | D264: =WEEKDAY(C264, 2) -> 6
C265: 46285 | D265: =WEEKDAY(C265, 2) -> 7
C266: 46286 | D266: =WEEKDAY(C266, 2) -> 1
C267: 46287 | D267: =WEEKDAY(C267, 2) -> 2
C268: 46288 | D268: =WEEKDAY(C268, 2) -> 3
C269: 46289 | D269: =WEEKDAY(C269, 2) -> 4
C270: 46290 | D270: =WEEKDAY(C270, 2) -> 5
C271: 46291 | D271: =WEEKDAY(C271, 2) -> 6
C272: 46292 | D272: =WEEKDAY(C272, 2) -> 7
C273: 46293 | D273: =WEEKDAY(C273, 2) -> 1
C274: 46294 | D274: =WEEKDAY(C274, 2) -> 2
C275: 46295 | D275: =WEEKDAY(C275, 2) -> 3
... C367: 46387 | D367: =WEEKDAY(C367, 2) -> 4

Sheet Letter Tracking
A1: Dictator | B1: Copies | C1: K Number | D1: Patient Name | E1: Clinic Code | F1: Clinic Date | G1: Date Typed | H1: Bighand ID | I1: Length | J1: Notes | K1: Authorised | L1: Days to authorise | M1: Hidden column for calcs
G2: 46023 | K2: n | L2: =IF(K2="y", TODAY()-G2, "") | M2: =Table1[[#This Row],[Length]]/60 -> 0
K3: n | L3: =IF(K3="y", TODAY()-G3, "") | M3: =Table1[[#This Row],[Length]]/60 -> 0
K4: n | L4: =IF(K4="y", TODAY()-G4, "") | M4: =Table1[[#This Row],[Length]]/60 -> 0 | P4: What has been done?
K5: n | L5: =IF(K5="y", TODAY()-G5, "") | M5: =Table1[[#This Row],[Length]]/60 -> 0 | P5: Switched position of clinic code to the left of clinic date as this matches
K6: n | L6: =IF(K6="y", TODAY()-G6, "") | M6: =Table1[[#This Row],[Length]]/60 -> 0 | P6: the previous spreadsheets that we are switching from and saves effort when transferring information for printing
K7: n | L7: =IF(K7="y", TODAY()-G7, "") | M7: =Table1[[#This Row],[Length]]/60 -> 0
K8: n | L8: =IF(K8="y", TODAY()-G8, "") | M8: =Table1[[#This Row],[Length]]/60 -> 0 | P8: Columns resized to more accurately reflect data
K9: n | L9: =IF(K9="y", TODAY()-G9, "") | M9: =Table1[[#This Row],[Length]]/60 -> 0
K10: n | L10: =IF(K10="y", TODAY()-G10, "") | M10: =Table1[[#This Row],[Length]]/60 -> 0 | P10: Additional columns added to figure out days taken to authorise
K11: n | L11: =IF(K11="y", TODAY()-G11, "") | M11: =Table1[[#This Row],[Length]]/60 -> 0 | P11: calc can be hidden and days can be done. Need to hide the value and only have it come out
K12: n | L12: =IF(K12="y", TODAY()-G12, "") | M12: =Table1[[#This Row],[Length]]/60 -> 0 | P12: when there's data
K13: n | L13: =IF(K13="y", TODAY()-G13, "") | M13: =Table1[[#This Row],[Length]]/60 -> 0
K14: n | L14: =IF(K14="y", TODAY()-G14, "") | M14: =Table1[[#This Row],[Length]]/60 -> 0 | P14: Added days taken to authorise (for future analytics)
K15: n | L15: =IF(K15="y", TODAY()-G15, "") | M15: =Table1[[#This Row],[Length]]/60 -> 0
K16: n | L16: =IF(K16="y", TODAY()-G16, "") | M16: =Table1[[#This Row],[Length]]/60 -> 0
K17: n | L17: =IF(K17="y", TODAY()-G17, "") | M17: =Table1[[#This Row],[Length]]/60 -> 0
K18: n | L18: =IF(K18="y", TODAY()-G18, "") | M18: =Table1[[#This Row],[Length]]/60 -> 0
K19: n | L19: =IF(K19="y", TODAY()-G19, "") | M19: =Table1[[#This Row],[Length]]/60 -> 0
K20: n | L20: =IF(K20="y", TODAY()-G20, "") | M20: =Table1[[#This Row],[Length]]/60 -> 0
K21: n | L21: =IF(K21="y", TODAY()-G21, "") | M21: =Table1[[#This Row],[Length]]/60 -> 0
K22: n | L22: =IF(K22="y", TODAY()-G22, "") | M22: =Table1[[#This Row],[Length]]/60 -> 0
K23: n | L23: =IF(K23="y", TODAY()-G23, "") | M23: =Table1[[#This Row],[Length]]/60 -> 0
K24: n | L24: =IF(K24="y", TODAY()-G24, "") | M24: =Table1[[#This Row],[Length]]/60 -> 0
K25: n | L25: =IF(K25="y", TODAY()-G25, "") | M25: =Table1[[#This Row],[Length]]/60 -> 0
K26: n | L26: =IF(K26="y", TODAY()-G26, "") | M26: =Table1[[#This Row],[Length]]/60 -> 0
... K50: n | L50: =IF(K50="y", TODAY()-G50, "") | M50: =Table1[[#This Row],[Length]]/60 -> 0
K51: n | L51: =IF(K51="y", TODAY()-G51, "") | M51: =Table1[[#This Row],[Length]]/60 -> 0 | P51: Also add colours for if date and associated name then add to inbox for tracking?
K52: n | L52: =IF(K52="y", TODAY()-G52, "") | M52: =Table1[[#This Row],[Length]]/60 -> 0
K53: n | L53: =IF(K53="y", TODAY()-G53, "") | M53: =Table1[[#This Row],[Length]]/60 -> 0
K54: n | L54: =IF(K54="y", TODAY()-G54, "") | M54: =Table1[[#This Row],[Length]]/60 -> 0
K55: n | L55: =IF(K55="y", TODAY()-G55, "") | M55: =Table1[[#This Row],[Length]]/60 -> 0
K56: n | L56: =IF(K56="y", TODAY()-G56, "") | M56: =Table1[[#This Row],[Length]]/60 -> 0
K57: n | L57: =IF(K57="y", TODAY()-G57, "") | M57: =Table1[[#This Row],[Length]]/60 -> 0
K58: n | L58: =IF(K58="y", TODAY()-G58, "") | M58: =Table1[[#This Row],[Length]]/60 -> 0
K59: n | L59: =IF(K59="y", TODAY()-G59, "") | M59: =Table1[[#This Row],[Length]]/60 -> 0
K60: n | L60: =IF(K60="y", TODAY()-G60, "") | M60: =Table1[[#This Row],[Length]]/60 -> 0
K61: n | L61: =IF(K61="y", TODAY()-G61, "") | M61: =Table1[[#This Row],[Length]]/60 -> 0
K62: n | L62: =IF(K62="y", TODAY()-G62, "") | M62: =Table1[[#This Row],[Length]]/60 -> 0
K63: n | L63: =IF(K63="y", TODAY()-G63, "") | M63: =Table1[[#This Row],[Length]]/60 -> 0
...

Sheet Printing
A1: Printing: | H1: #Copies: | I1: #USER | K1: Code | L1: Clinic Date | M1: Date Typed
H2: high prio
A3: #Copies: | B3: #USER | D3: Code | E3: Clinic Date | F3: Date Typed
A4: non prio

Sheet Spare Table
A1: Dictator | B1: Copies | C1: K Number | D1: Patient Name | E1: Clinic Date | F1: Date Typed | G1: Clinic Code | H1: Bighand ID | I1: Length | J1: Notes | K1: Authorised | L1: Hidden column for calcs
K2: n | L2: =Table13[[#This Row],[Length]]/60 -> 0
K3: n | L3: =Table13[[#This Row],[Length]]/60 -> 0
K4: n | L4: =Table13[[#This Row],[Length]]/60 -> 0
K5: n | L5: =Table13[[#This Row],[Length]]/60 -> 0
K6: n | L6: =Table13[[#This Row],[Length]]/60 -> 0
K7: n | L7: =Table13[[#This Row],[Length]]/60 -> 0
K8: n | L8: =Table13[[#This Row],[Length]]/60 -> 0
K9: n | L9: =Table13[[#This Row],[Length]]/60 -> 0
K10: n | L10: =Table13[[#This Row],[Length]]/60 -> 0
K11: n | L11: =Table13[[#This Row],[Length]]/60 -> 0
K12: n | L12: =Table13[[#This Row],[Length]]/60 -> 0
K13: n | L13: =Table13[[#This Row],[Length]]/60 -> 0
... K2000: n | L2000: =Table13[[#This Row],[Length]]/60 -> 0
